Workbook
Name Anomaly_Benford_Verdict: '20_Anomaly_Detection'!$I$19
Name Anomaly_Earnings_Verdict: '20_Anomaly_Detection'!$G$42
Name Anomaly_Master_Verdict: '20_Anomaly_Detection'!$C$49
Name Anomaly_RollingZ_Count: '20_Anomaly_Detection'!$G$31
Name Anomaly_RollingZ_Verdict: '20_Anomaly_Detection'!$H$31
Name APIGrossIncome: '0_Setup'!$C$87
Name Bankable_Breach_Week: '21_Forecasting_Engine'!$D$64
Name BorrowerName: '0_Setup'!$C$5
Name CAM_Para1: '22_Credit_Memorandum'!$B$16
Name CAM_Para2: '22_Credit_Memorandum'!$B$19
Name CAM_Para3: '22_Credit_Memorandum'!$B$22
Name CAM_Para4: '22_Credit_Memorandum'!$B$25
Name CAM_Synopsis: '22_Credit_Memorandum'!$A$5
Name Cascade_Breakpoint: '15_Stress_Test'!$C$105
Name Cascade_DSCR: '15_Stress_Test'!$C$98
Name Cascade_Selected_Scenario: '15_Stress_Test'!$C$71
Name Cascade_Severity: '15_Stress_Test'!$C$72
Name Cascade_Verdict: '15_Stress_Test'!$E$98
Name CashFlow_MaxFunding: '18_13W_Cash_Flow'!$P$30
Name CashFlow_MinAcrossWeeks: '18_13W_Cash_Flow'!$O$29
Name CashFlow_MinClosing: '18_13W_Cash_Flow'!$P$29
Name ChapterXIA_AggExposure: '10_Credit_Limits'!$E$37
Name ChapterXIA_BankShare: '10_Credit_Limits'!$E$39
Name ChapterXIA_Status: '10_Credit_Limits'!$E$40
Name CurrentEstCol: '0_Setup'!$C$43
Name CurrentFY: '0_Setup'!$C$14
Name CustomerID: '0_Setup'!$C$6
Name DataSource: '0_Setup'!$C$86
Name DCCO_Year: '0_Setup'!$C$83
Name ESG_TotalScore: '16_ESG_Scorecard'!$D$21
Name EWS_CriticalCount: '17_Advanced_EWS'!$D$56
Name EWS_HighCount: '17_Advanced_EWS'!$E$56
Name EWS_TotalPoints: '17_Advanced_EWS'!$F$56
Name EWS_Verdict: '17_Advanced_EWS'!$G$56
Name ExistingFB_TL: '0_Setup'!$B$21
Name ExistingFB_WC: '0_Setup'!$B$20
Name ExistingNFB: '0_Setup'!$B$22
Name ExternalRating: '0_Setup'!$C$9
Name FirstFY: '0_Setup'!$C$12
Name Forecast_Cash_Yr1: '21_Forecasting_Engine'!$E$8
Name Forecast_EBITDA_Yr1: '21_Forecasting_Engine'!$E$7
Name Forecast_Sales_Yr1: '21_Forecasting_Engine'!$E$6
Name IndustryName: '0_Setup'!$C$7
Name InternalRating: '0_Setup'!$C$8
Name LastFY: '0_Setup'!$C$13
Name LastProjCol: '0_Setup'!$C$44
Name LatestAudCol: '0_Setup'!$C$40
Name LatestEstCol: '0_Setup'!$C$41
Name Liquidity_Breach_Week: '21_Forecasting_Engine'!$D$63
Name MaxDPOStretch: '0_Setup'!$F$31
Name MaxDSOIncrease: '0_Setup'!$F$30
Name MaxInvDays: '0_Setup'!$F$29
Name MaxLeverage: '0_Setup'!$C$30
Name MaxNWCErosion: '0_Setup'!$F$28
Name MaxTOLTNW: '0_Setup'!$C$29
Name Min_Projected_Cash: '21_Forecasting_Engine'!$D$65
Name MinCR: '0_Setup'!$C$26
Name MinDSCR_Any: '0_Setup'!$C$27
Name MinDSCR_Avg: '0_Setup'!$C$28
Name MinFACR: '0_Setup'!$F$27

Sheet 0A_Executive_Dashboard
A1: CMA AUTO-ANALYTICS · EXECUTIVE DASHBOARD · SANCTION COMMITTEE SNAPSHOT
A2: =IF(BorrowerName="","[Borrower Not Set]","Borrower: "&BorrowerName) -> [Borrower Not Set] | C2: =IF(IndustryName="","Industry: —","Industry: "&IndustryName) -> Industry: — | E2: =IF(ProposalType="","Proposal: —","Proposal: "&ProposalType) -> Proposal: — | G2: =TODAY() -> 46150
B4: 📊 KEY PERFORMANCE INDICATORS | G4: 🔴 RISK SCORE & RECOMMENDATION
B5: Metric | C5: Latest Aud | D5: Threshold | E5: Status | G5: Score Basis
B6: Net Sales (₹ Cr) | C6: =IFERROR(INDEX('2_Operating_Statement'!C13:N13,1,LatestAudCol),0) -> 0 | D6: — (trend) | E6: =IF(IFERROR(INDEX('2_Operating_Statement'!C13:N13,1,LatestAudCol),0)>0,"🟢 POSITIVE","⚠ ZERO/NEG") -> ⚠ ZERO/NEG | G6: "Absolute revenue base — check YoY trajectory"
B7: Sales Growth YoY (Latest Aud) | C7: =IFERROR(INDEX('8_Performance_Indicators'!C8:N8,1,LatestAudCol),0) | D7: ≥ MinSalesGrowth | E7: =IF(IFERROR(INDEX('8_Performance_Indicators'!C8:N8,1,LatestAudCol),0)>=0.1,"🟢 STRONG",IF(IFERROR(INDEX('8_Performance_Indicators'!C8:N8,1,LatestAudCol),0)>=MinSalesGrowth,"🟡 WATCH","🔴 WEAK")) -> 🟢 STRONG | G7: "Revenue momentum — verify with GST/banking"
B8: EBITDA Margin | C8: =IFERROR((IFERROR(INDEX('2_Operating_Statement'!C33:N33,1,LatestAudCol),0)+IFERROR(INDEX('2_Operating_Statement'!C24:N24,1,LatestAudCol),0))/IF(IFERROR(INDEX('2_Operating_Statement'!C13:N13,1,LatestAudCol),0)=0,1,IFERROR(INDEX('2_Operating_Statement'!C13:N13,1,LatestAudCol),0)),0) -> 0 | D8: ≥ 10% (watch) | E8: =IF(IFERROR((IFERROR(INDEX('2_Operating_Statement'!C33:N33,1,LatestAudCol),0)+IFERROR(INDEX('2_Operating_Statement'!C24:N24,1,LatestAudCol),0))/IF(IFERROR(INDEX('2_Operating_Statement'!C13:N13,1,LatestAudCol),0)=0,1,IFERROR(INDEX('2_Operating_Statement'!C13:N13,1,LatestAudCol),0)),0)>=0.1,"🟢 HEALTHY",IF(IFERROR((IFERROR(INDEX('2_Operating_Statement'!C33:N33,1,LatestAudCol),0)+IFERROR(INDEX('2_Operating_Statement'!C24:N24,1,LatestAudCol),0))/IF(IFERROR(INDEX('2_Operating_Statement'!C13:N13,1,LatestAudCol),0)=0,1,IFERROR(INDEX('2_Operating_Statement'!C13:N13,1,LatestAudCol),0)),0)>=0.05,"🟡 MARGINAL","🔴 THIN")) -> 🔴 THIN | G8: "Cash-generating capacity — EBITDA/Sales"
B9: PAT Margin | C9: =IFERROR(INDEX('8_Performance_Indicators'!C10:N10,1,LatestAudCol),0) -> 0 | D9: ≥ 2% | E9: =IF(IFERROR(INDEX('8_Performance_Indicators'!C10:N10,1,LatestAudCol),0)>=0.05,"🟢 STRONG",IF(IFERROR(INDEX('8_Performance_Indicators'!C10:N10,1,LatestAudCol),0)>=0.02,"🟡 OK","🔴 THIN")) -> 🔴 THIN | G9: "Retained earnings power"
B10: Current Ratio | C10: =IFERROR(INDEX('8_Performance_Indicators'!C14:N14,1,LatestAudCol),0) -> 0 | D10: ≥ MinCR | E10: =IF(IFERROR(INDEX('8_Performance_Indicators'!C14:N14,1,LatestAudCol),0)>=MinCR+0.3,"🟢 STRONG",IF(IFERROR(INDEX('8_Performance_Indicators'!C14:N14,1,LatestAudCol),0)>=MinCR,"🟡 WATCH","🔴 BREACH")) -> 🔴 BREACH | G10: "Short-term solvency buffer"
B11: TOL / TNW | C11: =IFERROR(INDEX('8_Performance_Indicators'!C19:N19,1,LatestAudCol),0) -> 0 | D11: ≤ MaxTOLTNW | E11: =IF(IFERROR(INDEX('8_Performance_Indicators'!C19:N19,1,LatestAudCol),0)<=0,"🔴 NEG TNW",IF(IFERROR(INDEX('8_Performance_Indicators'!C19:N19,1,LatestAudCol),0)<=MaxTOLTNW-1,"🟢 LOW LVRG",IF(IFERROR(INDEX('8_Performance_Indicators'!C19:N19,1,LatestAudCol),0)<=MaxTOLTNW,"🟡 WATCH","🔴 BREACH"))) -> 🔴 NEG TNW | G11: "Balance sheet leverage — outside liabilities vs equity"
B12: Interest Coverage (ICR) | C12: =IFERROR(INDEX('8_Performance_Indicators'!C23:N23,1,LatestAudCol),0) -> 0 | D12: ≥ MinICR | E12: =IF(IFERROR(INDEX('8_Performance_Indicators'!C23:N23,1,LatestAudCol),0)<=0,"🔴 NEG/NIL",IF(IFERROR(INDEX('8_Performance_Indicators'!C23:N23,1,LatestAudCol),0)>=MinICR+1,"🟢 STRONG",IF(IFERROR(INDEX('8_Performance_Indicators'!C23:N23,1,LatestAudCol),0)>=MinICR,"🟡 OK","🔴 BREACH"))) -> 🔴 NEG/NIL | G12: "Operating profit coverage of interest cost"
B13: DSCR (Gross, Latest Aud Yr) | C13: =IFERROR(INDEX('4_DSCR'!C17:N17,1,LatestAudCol),0) -> 0 | D13: ≥ MinDSCR_Any | E13: =IF(IFERROR(INDEX('4_DSCR'!C17:N17,1,LatestAudCol),0)<=0,"🔴 NO DATA",IF(IFERROR(INDEX('4_DSCR'!C17:N17,1,LatestAudCol),0)>=2,"🟢 STRONG",IF(IFERROR(INDEX('4_DSCR'!C17:N17,1,LatestAudCol),0)>=MinDSCR_Any,"🟡 OK","🔴 BREACH"))) -> 🔴 NO DATA | G13: "Term loan debt service — cash accruals vs repayment"
B14: Cash Conversion Cycle (Days) | C14: =IFERROR(INDEX('8_Performance_Indicators'!C30:N30,1,LatestAudCol),0) -> 0 | D14: < 120 days | E14: =IF(IFERROR(INDEX('8_Performance_Indicators'!C30:N30,1,LatestAudCol),0)=0,"—",IF(IFERROR(INDEX('8_Performance_Indicators'!C30:N30,1,LatestAudCol),0)<90,"🟢 EFFICIENT",IF(IFERROR(INDEX('8_Performance_Indicators'!C30:N30,1,LatestAudCol),0)<120,"🟡 WATCH","🔴 STRETCHED"))) -> — | G14: "Inv days + DSO − DPO; WC efficiency"
B15: Red Flags Triggered (/ 30 tests) | C15: ='12_Red_Flags'!D47 -> 0 | D15: 0 preferred | E15: =IF('12_Red_Flags'!D47=0,"🟢 CLEAN",IF('12_Red_Flags'!D47<=3,"🟡 MINOR",IF('12_Red_Flags'!D47<=7,"🔴 MULTIPLE","🔴 MATERIAL"))) -> 🟢 CLEAN | G15: "Automated diagnostic battery — review each flag"
B17: 🚨 RED FLAG VERDICT & LENDING STANCE
B18: Total Tests Triggered | C18: Overall Risk Score (/ 30) | D18: Red Flag Verdict | E18: =IF('0B_Credit_Scoring'!D29>=75,"✅ STRONG APPROVE — Credit profile robust. Recommend sanction with standard covenants.",IF('0B_Credit_Scoring'!D29>=60,"⚠ APPROVE WITH CONDITIONS — Satisfactory profile with noted concerns. Enhanced monitoring required.",IF('0B_Credit_Scoring'!D29>=50,"⚠ CAUTIOUS — Marginal profile. Sanction only with strong mitigants and committee approval.",IF('0B_Credit_Scoring'!D29>=40,"🔴 HIGH RISK — Significant weaknesses. Defer / restructure before sanction.","🔴 DECLINE — Material concerns across multiple dimensions. Not recommended.")))) -> 🔴 DECLINE — Material concerns across multiple dimensions. Not recommended.
B19: ='12_Red_Flags'!D47 -> 0 | C19: ='12_Red_Flags'!D49 -> 0 | D19: ='12_Red_Flags'!D50 -> 0
B20: Credit Scoring Engine Score (see 0B_Credit_Scoring sheet):
B21: ='0B_Credit_Scoring'!G29 -> 14.1
B23: 💚 TOP 5 CREDIT STRENGTHS (auto-assessed) | G23: 🔴 TOP 5 RISKS
B24: =IF(IFERROR(INDEX('8_Performance_Indicators'!C10:N10,1,LatestAudCol),0)>=0.05,"✓ PAT Margin "&TEXT(IFERROR(INDEX('8_Performance_Indicators'!C10:N10,1,LatestAudCol),0),"0.0%")&" — profitable operations","—") -> — | G24: =IF(IFERROR(INDEX('8_Performance_Indicators'!C14:N14,1,LatestAudCol),0)<MinCR,"⚠ CR "&TEXT(IFERROR(INDEX('8_Performance_Indicators'!C14:N14,1,LatestAudCol),0),"0.00x")&" — liquidity breach (threshold "&TEXT(MinCR,"0.00x")&")","—") -> ⚠ CR 0.00x — liquidity breach (threshold 1.17x)
B25: =IF(IFERROR(INDEX('8_Performance_Indicators'!C14:N14,1,LatestAudCol),0)>=MinCR+0.3,"✓ Current Ratio "&TEXT(IFERROR(INDEX('8_Performance_Indicators'!C14:N14,1,LatestAudCol),0),"0.00x")&" — strong liquidity","—") -> — | G25: =IF(IFERROR(INDEX('8_Performance_Indicators'!C19:N19,1,LatestAudCol),0)>MaxTOLTNW,"⚠ TOL/TNW "&TEXT(IFERROR(INDEX('8_Performance_Indicators'!C19:N19,1,LatestAudCol),0),"0.0x")&" — high leverage","—") -> —
B26: =IF(IFERROR(INDEX('8_Performance_Indicators'!C19:N19,1,LatestAudCol),0)<2.5,"✓ TOL/TNW "&TEXT(IFERROR(INDEX('8_Performance_Indicators'!C19:N19,1,LatestAudCol),0),"0.0x")&" — conservative leverage","—") -> ✓ TOL/TNW 0.0x — conservative leverage | G26: =IF(IFERROR(INDEX('4_DSCR'!C17:N17,1,LatestAudCol),0)<MinDSCR_Any,"⚠ DSCR "&TEXT(IFERROR(INDEX('4_DSCR'!C17:N17,1,LatestAudCol),0),"0.00x")&" — debt coverage below minimum","—") -> ⚠ DSCR 0.00x — debt coverage below minimum
B27: =IF(IFERROR(INDEX('4_DSCR'!C17:N17,1,LatestAudCol),0)>=2,"✓ DSCR "&TEXT(IFERROR(INDEX('4_DSCR'!C17:N17,1,LatestAudCol),0),"0.00x")&" — robust debt coverage","—") -> — | G27: =IF(IFERROR(INDEX('8_Performance_Indicators'!C10:N10,1,LatestAudCol),0)<0.02,"⚠ PAT Margin "&TEXT(IFERROR(INDEX('8_Performance_Indicators'!C10:N10,1,LatestAudCol),0),"0.0%")&" — thin profitability","—") -> ⚠ PAT Margin 0.0% — thin profitability
B28: =IF(IFERROR(INDEX('8_Performance_Indicators'!C23:N23,1,LatestAudCol),0)>=3,"✓ ICR "&TEXT(IFERROR(INDEX('8_Performance_Indicators'!C23:N23,1,LatestAudCol),0),"0.00x")&" — strong interest cover","—") -> — | G28: =IF(IFERROR(INDEX('8_Performance_Indicators'!C8:N8,1,LatestAudCol),0)<MinSalesGrowth,"⚠ Sales Growth "&TEXT(IFERROR(INDEX('8_Performance_Indicators'!C8:N8,1,LatestAudCol),0),"0.0%")&" — revenue under pressure","—") -> —
A32: 🚨 REGULATORY COMPLIANCE & ADVANCED RISK STATUS
B33: Compliance Module | C33: Status / Score | D33: Regulator / Source | F33: Implication for Sanction Committee
B34: Chapter XIA — Current/OD Account | C34: =ChapterXIA_Status -> 🟢 NO RESTRICTION | D34: RBI Amendment Apr 2026 | F34: =IF(LEFT(ChapterXIA_Status,1)="🔴","🔴 Account operations restricted. Only Collection Account (T+2 sweep) permitted. NOT eligible for standard CC/OD operation. CRITICAL constraint for sanction.",IF(ChapterXIA_AggExposure<10,"🟢 Aggregate exposure < ₹10 Cr threshold — full operational flexibility.","🟢 Bank holds compliant share (≥10%) of aggregate banking exposure.")) -> 🟢 Aggregate exposure < ₹10 Cr threshold — full operational flexibility.
B35: Early Warning Signals (RBI MD) | C35: =TEXT(EWS_TotalPoints,"0")&" pts" -> 0 pts | D35: RBI Master Direction Jul 2024 | F35: =EWS_Verdict -> 🟢 NORMAL — STANDARD MONITORING
B36: ESG & Climate Resilience | C36: =TEXT(ESG_TotalScore,"0.0")&" /100" -> 50.0 /100 | D36: RBI Climate MD Nov 2025 | F36: =IF(ESG_TotalScore>=65,"🟢 Strong ESG profile — supports lending pricing and reputation.",IF(ESG_TotalScore>=50,"🟡 Adequate ESG — monitor BRSR disclosures and transition pathway.","🔴 Weak ESG profile — climate transition risk exposure. Consider pricing premium and ESG covenants.")) -> 🟡 Adequate ESG — monitor BRSR disclosures and transition pathway.
B37: 13-Week Cash Flow Liquidity | C37: ="₹"&TEXT(CashFlow_MinClosing,"0.00")&" Cr" -> ₹0.00 Cr | D37: Treasury Best Practice | F37: =IF(CashFlow_MinClosing<0,"🔴 ACUTE 13-WEEK LIQUIDITY DEFICIT — Existing WC limits insufficient to bridge cash conversion cycle. Reassess MPBF & DSRA structure.","🟢 Closing balance projected positive across 13-week horizon. Liquidity adequate.") -> 🟢 Closing balance projected positive across 13-week horizon. Liquidity adequate.
B38: Project Finance Overlay | C38: =IF(ProjectFinance="Yes","Active","N/A") -> N/A | D38: RBI Project Finance Dir 2025 | F38: =IF(ProjectFinance="Yes",IF(ProjectPhase="Under-Construction",IF(ProjectSector="Commercial Real Estate","⚠ Standard provisioning at 1.25% (CRE under-construction). Pricing must absorb elevated capital cost.",IF(ProjectSector="Infrastructure","⚠ Standard provisioning at 1.00% (Infrastructure under-construction). DSCR alerts suppressed pre-DCCO.","⚠ Project finance under construction — review provisioning per RBI Project Finance Directions 2025.")),"🟢 Project operational — standard provisioning (0.40%) applies."),"Not a project finance facility.") -> Not a project finance facility.
B39: Probabilistic Default Model (Ohlson) | C39: =IF('19_Ohlson_O_Score'!O7=0,"— No data —",TEXT(Ohlson_PD_Latest,"0.0%")&" PD") -> — No data — | D39: Logistic Regression Model | F39: =IF('19_Ohlson_O_Score'!O7=0,"— Populate financials to activate Ohlson model",IF(Ohlson_PD_Latest>=0.5,"🔴 SEVERE distress probability — model assigns >50% PD. Override risk grade ceiling to BB or below regardless of categorical score.",IF(Ohlson_PD_Latest>=0.2,"🟡 ELEVATED PD — investigate top driver flagged on 19_Ohlson_O_Score. Cross-check with categorical score for divergence.",IF(Ohlson_PD_Latest>=0.038,"🟠 WATCH — PD above Ohlson optimal cutoff (0.038) but below severe. Acceptable with covenants.","🟢 HEALTHY — PD below Ohlson optimal cutoff. Probabilistic model concurs with low default risk.")))) -> — Populate financials to activate Ohlson model
B40: Benford's Law (Forensic) | C40: =IF('20_Anomaly_Detection'!E17<30,"— Need ≥30 obs",TEXT('20_Anomaly_Detection'!E17,"0")&" obs") -> — Need ≥30 obs | D40: AICPA Forensic Std | F40: =IF('20_Anomaly_Detection'!E17<30,"⚪ Insufficient sample — paste ≥30 monetary entries into 20_Anomaly_Detection col M",Anomaly_Benford_Verdict&" — see 20_Anomaly_Detection Section A") -> ⚪ Insufficient sample — paste ≥30 monetary entries into 20_Anomaly_Detection col M
B41: Rolling Z-Score (Trend) | C41: =Anomaly_RollingZ_Count&"/6 metrics" -> 0/6 metrics | D41: Statistical Z-Test | F41: =Anomaly_RollingZ_Verdict&" — see 20_Anomaly_Detection Section B" -> 🟢 No statistical outliers — see 20_Anomaly_Detection Section B
B42: Earnings Manipulation (Beneish) | C42: =TEXT('20_Anomaly_Detection'!F42,"0")&"/5 signals" -> 0/5 signals | D42: Beneish M-Score | F42: =Anomaly_Earnings_Verdict&" — see 20_Anomaly_Detection Section C" -> 🟢 No manipulation signature detected — see 20_Anomaly_Detection Section C
B43: Causal Cascade DSCR (selected scenario) | C43: =TEXT(Cascade_DSCR,"0.00x") -> 0.00x | D43: =Cascade_Selected_Scenario&" @ "&TEXT(Cascade_Severity,"0%") -> Brent Oil Shock @ 100% | F43: =Cascade_Verdict&" — see 15_Stress_Test Section F.4 | Breakpoint: "&Cascade_Breakpoint -> 🔴 DEBT SERVICE FAILURE — see 15_Stress_Test Section F.4 | Breakpoint: ⚠ Insufficient data
B44: 13-Week Forecast (FORECAST.ETS) | C44: =Min_Projected_Cash -> ⚠ Paste ≥8 weeks of historical receipts/disbursements first | D44: Holt-Winters ETS | F44: =IF(LEFT(Bankable_Breach_Week,1)="🔴",Bankable_Breach_Week,IF(LEFT(Liquidity_Breach_Week,1)="✓","🟢 "&Liquidity_Breach_Week,"🟠 "&Liquidity_Breach_Week)) -> 🟢 ✓ No cash-negative week in 13W horizon
B45: Annual Forecast Yr+1 (Net Sales) | C45: =IF(NOT(ISNUMBER(Forecast_Sales_Yr1)),"— Need ≥4 yrs history",TEXT(Forecast_Sales_Yr1,"#,##0")&" Cr") -> — Need ≥4 yrs history | D45: FORECAST.ETS | F45: =IF(NOT(ISNUMBER(Forecast_Sales_Yr1)),"⚪ Insufficient annual history (need ≥4 audited yrs)","Forecast YoY: "&TEXT(IFERROR(Forecast_Sales_Yr1/INDEX('2_Operating_Statement'!C13:N13,1,LatestAudCol)-1,0),"+0.0%;-0.0%")&" — see 21_Forecasting_Engine Section A") -> ⚪ Insufficient annual history (need ≥4 audited yrs)
B46: Credit Justification Memorandum | C46: ="See sheet 22_Credit_Memorandum" -> See sheet 22_Credit_Memorandum | D46: Auto-NLG (Module 5) | F46: =IFERROR(IF(OR(IFERROR(Ohlson_PD_Latest,0)>=0.5,LEFT(IFERROR(Anomaly_Master_Verdict,""),1)="🔴",IFERROR(Cascade_DSCR,99)<1,LEFT(IFERROR(Bankable_Breach_Week,""),1)="🔴"),"🔴 DECLINE recommended",IF(OR(IFERROR(Ohlson_PD_Latest,0)>=0.2,LEFT(IFERROR(Anomaly_Master_Verdict,""),1)="🟠",IFERROR(Cascade_DSCR,99)<MinDSCR_Any,LEFT(IFERROR(EWS_Verdict,""),1)="🚨"),"🟠 APPROVE WITH COVENANTS",IF(OR(IFERROR(Cascade_DSCR,99)<1.5,LEFT(IFERROR(EWS_Verdict,""),1)="⚠"),"🟡 APPROVE WITH STANDARD COVENANTS","🟢 APPROVE at standard terms"))),"⚪ Awaiting data") -> 🔴 DECLINE recommended

Sheet 0B_Credit_Scoring
A1: DYNAMIC CREDIT SCORING ENGINE | Weighted 10-Category Risk Model
A2: =IF(BorrowerName="","[Complete borrower name in 0_Setup]","Borrower: "&BorrowerName&" | Industry: "&IF(IndustryName="","—",IndustryName)&" | Proposal: "&IF(ProposalType="","—",ProposalType)) -> [Complete borrower name in 0_Setup]
B4: Scoring Category | C4: Weight % | D4: Auto-Score (0-10) | E4: Manual Override | F4: Effective Score | G4: Weighted Score | H4: Basis / Commentary
B6: 1. Profitability | C6: 0.14 | D6: =IFERROR((IF(IFERROR(INDEX('8_Performance_Indicators'!C9:N9,1,LatestAudCol),0)>=0.15,10,IF(IFERROR(INDEX('8_Performance_Indicators'!C9:N9,1,LatestAudCol),0)>=0.1,8,IF(IFERROR(INDEX('8_Performance_Indicators'!C9:N9,1,LatestAudCol),0)>=0.07,6,IF(IFERROR(INDEX('8_Performance_Indicators'!C9:N9,1,LatestAudCol),0)>=0.05,4,IF(IFERROR(INDEX('8_Performance_Indicators'!C9:N9,1,LatestAudCol),0)>=0.03,2,0)))))+IF(IFERROR(INDEX('8_Performance_Indicators'!C10:N10,1,LatestAudCol),0)>=0.08,10,IF(IFERROR(INDEX('8_Performance_Indicators'!C10:N10,1,LatestAudCol),0)>=0.05,8,IF(IFERROR(INDEX('8_Performance_Indicators'!C10:N10,1,LatestAudCol),0)>=0.03,6,IF(IFERROR(INDEX('8_Performance_Indicators'!C10:N10,1,LatestAudCol),0)>=0.02,4,IF(IFERROR(INDEX('8_Performance_Indicators'!C10:N10,1,LatestAudCol),0)>=0.01,2,0))))))/2,0) -> 0 | F6: =IF(E6<>"",E6,D6) -> 0 | G6: =F6*C6 -> 0 | H6: "OPM & PAT Margin vs thresholds. ≥15%/≥8%→10; ≥5%/≥2%→4"
B7: 2. Liquidity | C7: 0.11 | D7: =IFERROR((IF(IFERROR(INDEX('8_Performance_Indicators'!C14:N14,1,LatestAudCol),0)>=2,10,IF(IFERROR(INDEX('8_Performance_Indicators'!C14:N14,1,LatestAudCol),0)>=1.5,8,IF(IFERROR(INDEX('8_Performance_Indicators'!C14:N14,1,LatestAudCol),0)>=1.33,6,IF(IFERROR(INDEX('8_Performance_Indicators'!C14:N14,1,LatestAudCol),0)>=1.17,4,IF(IFERROR(INDEX('8_Performance_Indicators'!C14:N14,1,LatestAudCol),0)>=1,2,0)))))+IF(IFERROR(INDEX('8_Performance_Indicators'!C15:N15,1,LatestAudCol),0)>=1.5,10,IF(IFERROR(INDEX('8_Performance_Indicators'!C15:N15,1,LatestAudCol),0)>=1.2,8,IF(IFERROR(INDEX('8_Performance_Indicators'!C15:N15,1,LatestAudCol),0)>=1,6,IF(IFERROR(INDEX('8_Performance_Indicators'!C15:N15,1,LatestAudCol),0)>=0.8,4,IF(IFERROR(INDEX('8_Performance_Indicators'!C15:N15,1,LatestAudCol),0)>=0.6,2,0))))))/2,0) -> 0 | F7: =IF(E7<>"",E7,D7) -> 0 | G7: =F7*C7 -> 0 | H7: "Current Ratio & Quick Ratio. CR≥2.0/QR≥1.5→10; CR<MinCR→≤4"
B8: 3. Leverage | C8: 0.11 | D8: =IFERROR(IF(IFERROR(INDEX('8_Performance_Indicators'!C19:N19,1,LatestAudCol),0)<=0,0,IF(10-IFERROR(INDEX('8_Performance_Indicators'!C19:N19,1,LatestAudCol),0)*2>=7,10,IF(10-IFERROR(INDEX('8_Performance_Indicators'!C19:N19,1,LatestAudCol),0)*2>=5,8,IF(10-IFERROR(INDEX('8_Performance_Indicators'!C19:N19,1,LatestAudCol),0)*2>=3,6,IF(10-IFERROR(INDEX('8_Performance_Indicators'!C19:N19,1,LatestAudCol),0)*2>=1,4,IF(10-IFERROR(INDEX('8_Performance_Indicators'!C19:N19,1,LatestAudCol),0)*2>=-1,2,0)))))),0) -> 0 | F8: =IF(E8<>"",E8,D8) -> 0 | G8: =F8*C8 -> 0 | H8: "TOL/TNW — lower is better. ≤1.5→10; ≤2.5→6; >MaxTOLTNW→2"
B9: 4. Debt Coverage | C9: 0.14 | D9: =IFERROR((IF(IFERROR(INDEX('4_DSCR'!C17:N17,1,LatestAudCol),0)>=2.5,10,IF(IFERROR(INDEX('4_DSCR'!C17:N17,1,LatestAudCol),0)>=2,8,IF(IFERROR(INDEX('4_DSCR'!C17:N17,1,LatestAudCol),0)>=1.75,6,IF(IFERROR(INDEX('4_DSCR'!C17:N17,1,LatestAudCol),0)>=1.25,4,IF(IFERROR(INDEX('4_DSCR'!C17:N17,1,LatestAudCol),0)>=1,2,0)))))+IF(IFERROR(INDEX('8_Performance_Indicators'!C23:N23,1,LatestAudCol),0)>=5,10,IF(IFERROR(INDEX('8_Performance_Indicators'!C23:N23,1,LatestAudCol),0)>=4,8,IF(IFERROR(INDEX('8_Performance_Indicators'!C23:N23,1,LatestAudCol),0)>=3,6,IF(IFERROR(INDEX('8_Performance_Indicators'!C23:N23,1,LatestAudCol),0)>=1.5,4,IF(IFERROR(INDEX('8_Performance_Indicators'!C23:N23,1,LatestAudCol),0)>=1,2,0))))))/2,0) -> 0 | F9: =IF(E9<>"",E9,D9) -> 0 | G9: =F9*C9 -> 0 | H9: "DSCR & ICR. DSCR≥2.5/ICR≥5→10. Breach of either→≤4"
B10: 5. Banking Conduct | C10: 0.08 | D10: =IF(E14<>"",E14,5) -> 5 | F10: =IF(E10<>"",E10,D10) -> 5 | G10: =F10*C10 -> 0.4 | H10: "Manual input (0-10). Default=5. Rate based on utilisation, cheque returns, overdrawing, EMI history"
B11: 6. Industry Outlook | C11: 0.08 | D11: =IFERROR(IF('0_Setup'!C68="Positive",9,IF('0_Setup'!C68="Stable",7,IF('0_Setup'!C68="Cautious",5,IF('0_Setup'!C68="Negative",3,5)))),5) -> 5 | F11: =IF(E11<>"",E11,D11) -> 5 | G11: =F11*C11 -> 0.4 | H11: "Auto-pulled from Industry_Outlook via Setup. Positive→9; Stable→7; Cautious→5; Negative→3"
B12: 7. Financial Trend Stability | C12: 0.1 | D12: =IFERROR(MAX(0,10-COUNTIF('12_Red_Flags'!F5:F44,"⚠*")*1.2),0) -> 1.6 | F12: =IF(E12<>"",E12,D12) -> 1.6 | G12: =F12*C12 -> 0.16 | H12: "Deducts 1.2 pts per red flag triggered. Clean sheet (0 flags)→10; 8 flags→~0"
B13: 8. Working Capital Discipline | C13: 0.08 | D13: =IFERROR(IF(365/IFERROR(INDEX('8_Performance_Indicators'!C30:N30,1,LatestAudCol),0)>=6,10,IF(365/IFERROR(INDEX('8_Performance_Indicators'!C30:N30,1,LatestAudCol),0)>=4,8,IF(365/IFERROR(INDEX('8_Performance_Indicators'!C30:N30,1,LatestAudCol),0)>=3,6,IF(365/IFERROR(INDEX('8_Performance_Indicators'!C30:N30,1,LatestAudCol),0)>=2,4,IF(365/IFERROR(INDEX('8_Performance_Indicators'!C30:N30,1,LatestAudCol),0)>=1,2,0))))),0) -> 0 | F13: =IF(E13<>"",E13,D13) -> 0 | G13: =F13*C13 -> 0 | H13: "CCC efficiency. CCC<60d→10; CCC<90d→8; CCC>180d→2. Zero CCC treated as efficient"
B14: 9. Promoter Contribution | C14: 0.07 | D14: =IFERROR(IF(IFERROR(INDEX('3_Balance_Sheet'!C52:N52,1,LatestAudCol),0)/IF(IFERROR(INDEX('3_Balance_Sheet'!C52:N52,1,LatestAudCol),0)+IFERROR(INDEX('3_Balance_Sheet'!C39:N39,1,LatestAudCol),0)=0,1,IFERROR(INDEX('3_Balance_Sheet'!C52:N52,1,LatestAudCol),0)+IFERROR(INDEX('3_Balance_Sheet'!C39:N39,1,LatestAudCol),0))>=0.5,10,IF(IFERROR(INDEX('3_Balance_Sheet'!C52:N52,1,LatestAudCol),0)/IF(IFERROR(INDEX('3_Balance_Sheet'!C52:N52,1,LatestAudCol),0)+IFERROR(INDEX('3_Balance_Sheet'!C39:N39,1,LatestAudCol),0)=0,1,IFERROR(INDEX('3_Balance_Sheet'!C52:N52,1,LatestAudCol),0)+IFERROR(INDEX('3_Balance_Sheet'!C39:N39,1,LatestAudCol),0))>=0.4,8,IF(IFERROR(INDEX('3_Balance_Sheet'!C52:N52,1,LatestAudCol),0)/IF(IFERROR(INDEX('3_Balance_Sheet'!C52:N52,1,LatestAudCol),0)+IFERROR(INDEX('3_Balance_Sheet'!C39:N39,1,LatestAudCol),0)=0,1,IFERROR(INDEX('3_Balance_Sheet'!C52:N52,1,LatestAudCol),0)+IFERROR(INDEX('3_Balance_Sheet'!C39:N39,1,LatestAudCol),0))>=0.3,6,IF(IFERROR(INDEX('3_Balance_Sheet'!C52:N52,1,LatestAudCol),0)/IF(IFERROR(INDEX('3_Balance_Sheet'!C52:N52,1,LatestAudCol),0)+IFERROR(INDEX('3_Balance_Sheet'!C39:N39,1,LatestAudCol),0)=0,1,IFERROR(INDEX('3_Balance_Sheet'!C52:N52,1,LatestAudCol),0)+IFERROR(INDEX('3_Balance_Sheet'!C39:N39,1,LatestAudCol),0))>=0.25,4,IF(IFERROR(INDEX('3_Balance_Sheet'!C52:N52,1,LatestAudCol),0)/IF(IFERROR(INDEX('3_Balance_Sheet'!C52:N52,1,LatestAudCol),0)+IFERROR(INDEX('3_Balance_Sheet'!C39:N39,1,LatestAudCol),0)=0,1,IFERROR(INDEX('3_Balance_Sheet'!C52:N52,1,LatestAudCol),0)+IFERROR(INDEX('3_Balance_Sheet'!C39:N39,1,LatestAudCol),0))>=0.2,2,0))))),0) -> 0 | F14: =IF(E14<>"",E14,D14) -> 0 | G14: =F14*C14 -> 0 | H14: "TNW/(TNW+TTL). ≥50%→10; ≥40%→8; ≥25%→4. Low promoter skin-in→lower score"
B15: 10. Projection Reliability | C15: 0.04 | D15: =IF(E23<>"",E23,5) -> 5 | F15: =IF(E15<>"",E15,D15) -> 5 | G15: =F15*C15 -> 0.2 | H15: "Manual input (0-10). Default=5. Assess: CAGR vs history, margin assumptions, capacity utilisation realism"
B16: 11. ESG Risk & Climate Resilience | C16: 0.05 | D16: =IFERROR(ESG_TotalScore/10,5) -> 5 | F16: =IF(E16<>"",E16,D16) -> 5 | G16: =F16*C16 -> 0.25 | H16: "Auto-pulled from 16_ESG_Scorecard total ÷ 10. Includes hard-to-abate sector penalty if applicable."
B27: SCORE SUMMARY | F27: Effective Score | G27: Weighted Score | H27: Score Basis / Guidance
F28: Total Weights Used | G28: TOTAL WEIGHTED SCORE | H28: Internal Risk Grade
F29: =SUM(C6:C16) -> 1 | G29: =SUM(G6:G16)*10 -> 14.1 | H29: =IF(G29>=80,"AAA — Excellent",IF(G29>=70,"AA — Strong",IF(G29>=60,"A — Good",IF(G29>=50,"BBB — Satisfactory",IF(G29>=40,"BB — Marginal","B/C — Weak / Decline"))))) -> B/C — Weak / Decline
F30: =IF(G29>=75,"✅ STRONG APPROVE — Recommend full sanction with standard conditions",IF(G29>=60,"⚠ APPROVE WITH CONDITIONS — Enhanced monitoring + specific covenants required",IF(G29>=50,"⚠ CAUTIOUS — Committee discretion; strong mitigants needed",IF(G29>=40,"🔴 HIGH RISK — Defer for improvement or partial sanction only","🔴 DECLINE — Material weaknesses; not recommended without major restructure")))) -> 🔴 DECLINE — Material weaknesses; not recommended without major restructure
B31: NOTE: Column E (Manual Override) accepts 0-10 inputs for Banking Conduct & Projection Reliability categories. Override any auto-score by entering a value in Column E. Auto-scores reflect latest audited year ratios only.

Sheet 0_Setup
A1: CMA AUTO-ANALYTICS TOOL | v2.0 | Borrower Setup
A2: Fill the YELLOW cells. Computed cells (green text) auto-derive. Year structure auto-builds across all data sheets based on inputs in Section 2.
A4: 1. BORROWER IDENTIFICATION
A5: Borrower Name | B5: → | F5: (Enter legal name)
A6: Customer / CIF ID | B6: → | F6: (Bank's customer ID)
A7: Industry / Activity | B7: → | F7: (Select from dropdown)
A8: Internal Rating | B8: → | F8: (e.g., SB-3, AAA-)
A9: External Rating | B9: → | F9: (e.g., CRISIL A+, ICRA AA-)
A11: 2. YEAR CONFIGURATION (drives column structure across all data sheets)
A12: First Fiscal Year (start year, e.g., 2022 for FY2022-23) | B12: → | C12: 2022 | F12: (Start year of first audited FY)
A13: Last Fiscal Year (start year, e.g., 2029 for FY2029-30) | B13: → | C13: 2029 | F13: (Start year of last projected FY)
A14: Current Fiscal Year (start year, e.g., 2025 for FY2025-26) | B14: → | C14: 2025 | F14: (THE CURRENT FY = Estimated)
A16: 3. PROPOSAL TYPE & LIMITS
A17: Proposal Type | B17: → | F17: (Select from dropdown)
A19: Facility | B19: Existing Limit (₹ Cr) | D19: Proposed Limit (₹ Cr) | F19: Notes
A20: FB - Working Capital
A21: FB - Term Loan Outstanding
A22: Non-Fund Based (LC/BG)
A23: Note: | B23: =IF(C17="Renewal at Existing Level","Renewal: only Existing limits used.",IF(C17="Renewal with Reduction","Renewal w/ Reduction: BOTH existing and proposed (lower) limits considered.",IF(OR(C17="Enhancement",C17="Greenfield Unit",C17="Fresh Sanction"),"Enhancement / Greenfield / Fresh: BOTH existing and proposed limits used.","Select proposal type above."))) -> Select proposal type above.
A25: 4. KEY THRESHOLDS (override defaults if industry/internal policy varies)
A26: Min Acceptable Current Ratio | B26: → | C26: 1.17 | D26: Acceptable Sales Growth Floor (Y-o-Y) | E26: → | F26: -0.05
A27: Min Acceptable DSCR (any year) | B27: → | C27: 1.25 | D27: Min FACR (TL Coverage) | E27: → | F27: 1.1
A28: Min Acceptable Avg DSCR | B28: → | C28: 1.5 | D28: Max NWC Erosion vs Prior Yr | E28: → | F28: -0.3
A29: Max Acceptable TOL/TNW | B29: → | C29: 4 | D29: Max Inventory-Days Increase | E29: → | F29: 0.4
A30: Max Acceptable Leverage (Debt/EBITDA) | B30: → | C30: 4.5 | D30: Max DSO Increase (Y-o-Y) | E30: → | F30: 0.3
A31: Min Acceptable Interest Coverage (ICR) | B31: → | C31: 1.5 | D31: Max DPO Stretch | E31: → | F31: 0.5
A33: 5. COMPUTED YEAR ARCHITECTURE (auto-derived — do not edit)
A34: Number of Fiscal Years | B34: → | C34: =$C$13-$C$12+1 -> 8 | F34: (Last - First + 1)
A35: Prior FY (year before current) | B35: → | C35: =$C$14-1 -> 2024 | F35: (Used for dual columns)
A36: Position of Prior FY | B36: → | C36: =$C$35-$C$12+1 -> 3 | F36: (1-indexed)
A37: Total Columns Used (incl. dual Estimated) | B37: → | C37: =$C$34+1 -> 9 | F37: (Capped at 12 max)
A39: ANCHOR INDICES
A40: Latest Audited (Audited/Provisional) col | B40: → | C40: =$C$36+1 -> 4
A41: Latest Estimated (dual, before Audited) | B41: → | C41: =$C$36 -> 3
A42: Prior Audited (year before dual) | B42: → | C42: =MAX($C$36-1,1) -> 2
A43: Current FY Estimated | B43: → | C43: =$C$36+2 -> 5
A44: Last Projected (terminal) | B44: → | C44: =$C$37 -> 9
A46: YEAR-LABEL HELPER TABLE (referenced by Row 4 of all data sheets)
A47: Col Idx | B47: Year Label | C47: Financial Type
A48: 1 | B48: =IF(1>$C$37,"",IF(1<$C$36,$C$12+1-1&"-"&RIGHT($C$12+1,2),IF(1=$C$36,$C$35&"-"&RIGHT($C$35+1,2),IF(1=$C$36+1,$C$35&"-"&RIGHT($C$35+1,2),IF(1=$C$36+2,$C$14&"-"&RIGHT($C$14+1,2),$C$14+(1-$C$36-2)&"-"&RIGHT($C$14+(1-$C$36-2)+1,2)))))) -> 2022-23 | C48: =IF(1>$C$37,"",IF(1<$C$36,"Audited",IF(1=$C$36,"Estimated",IF(1=$C$36+1,"Audited/Provisional",IF(1=$C$36+2,"Estimated","Projected"))))) -> Audited
...

Sheet 1_How_To_Use
A1: HOW TO USE THIS TOOL | v2.0
A3: STEP 1 — SETUP | B3: Open 0_Setup. Enter Borrower Name, Customer ID, Industry (dropdown), Internal & External rating. Set First/Last/Current fiscal years. Set Proposal Type. Enter Existing limits; for enhancements/greenfield/renewal-with-reduction also enter Proposed limits. Override threshold defaults if your internal policy differs.
A4: STEP 2 — YEAR ARCHITECTURE | B4: All data sheets auto-build year columns based on Setup Section 2. Year labels (row 4) and financial-type tags (row 5) update automatically. The dual 'Estimated/Audited-Provisional' columns appear immediately around the prior FY for direct comparison.
A5: STEP 3 — PASTE DATA | B5: Open SBI LLMS exports. Paste-Special → Values into each blue input cell across these sheets:
A6: Sheet 2 | B6: Operating Statement
A7: Sheet 3 | B7: Balance Sheet
A8: Sheet 4 | B8: DSCR Calculation
A9: Sheet 5 | B9: Holding Levels
A10: Sheet 6 | B10: Working Capital Assessment (MPBF II)
A11: Sheet 7 | B11: Funds Flow Statement
A12: STEP 4 — REVIEW ANALYTICS | B12: Sheets 8 (Performance Indicators) and 9 (Cross Checks) auto-populate. Red highlighting flags breaches; green = healthy; amber = caution. Δ column shows YoY (Latest Audited vs Prior Audited) movement.
A13: STEP 5 — CREDIT LIMITS & SECURITY | B13: Sheet 10: facility-wise limits (existing + proposed conditional on proposal type). Sheet 11: Primary & Collateral. Coverage % auto-computes.
A14: STEP 6 — RED FLAGS | B14: Sheet 12 — 30+ automated red-flag tests. Each breach is annotated with the underlying ratio/value AND the source columns/rows that drove the conclusion (full traceability).
... A16: STEP 8 — JUSTIFICATION | B16: Sheet 14 produces a polished, conversational, formal justification ready to paste into the CAM. Adjusts based on proposal type and existing/proposed limits.
A18: KEY MECHANICS
A19: Year Sequencing | B19: Cols C-N support up to 12 fiscal years. The dual Estimated+Audited columns sit just before the current FY for direct comparison of estimated vs realised.
A20: Trend Analysis | B20: All Δ columns and red-flag tests use 'Latest Audited' (the Audited/Provisional col) vs 'Prior Audited' (col 2 before that, skipping the dual Estimated). This captures real Y-o-Y, ignoring estimates.
A21: Industry Outlook | B21: Section 6 of Setup auto-pulls latest available industry data (CRISIL/ICRA/IBEF) for the selected sector. Refresh manually by editing the hidden Industry_Outlook sheet.
A22: Negative Numbers | B22: Display in (parentheses); zeros display as '-'. All ratios use IFERROR to avoid #DIV/0.
A24: WHEN TO RECALCULATE | B24: If formulas show 0s or stale numbers after pasting, press F9 (Excel) or Ctrl+Shift+F9 to force recalc. LibreOffice users: Tools → Cell Contents → Recalculate Hard.

Sheet 2_Operating_Statement
A1: =CONCATENATE("OPERATING STATEMENT | ₹ Crores | ", BorrowerName) -> OPERATING STATEMENT | ₹ Crores |
A2: Paste values from SBI LLMS Operating Statement → blue cells. Subtotals/totals auto-compute.
A3: Sr | B3: Particulars | C3: Yr 1 | D3: Yr 2 | E3: Yr 3 | F3: Yr 4 | G3: Yr 5 | H3: Yr 6 | I3: Yr 7 | J3: Yr 8 | K3: Yr 9 | L3: Yr 10 | M3: Yr 11 | N3: Yr 12 | O3: Δ Latest vs Prior Aud | P3: Auto-Comment
B4: Year → | C4: =INDEX('0_Setup'!$B$48:$B$59,1) -> 2022-23 | D4: =INDEX('0_Setup'!$B$48:$B$59,2) -> 2023-24 | E4: =INDEX('0_Setup'!$B$48:$B$59,3) -> 2024-25 | F4: =INDEX('0_Setup'!$B$48:$B$59,4) -> 2024-25 | G4: =INDEX('0_Setup'!$B$48:$B$59,5) -> 2025-26 | H4: =INDEX('0_Setup'!$B$48:$B$59,6) -> 2026-27 | I4: =INDEX('0_Setup'!$B$48:$B$59,7) -> 2027-28 | J4: =INDEX('0_Setup'!$B$48:$B$59,8) -> 2028-29 | K4: =INDEX('0_Setup'!$B$48:$B$59,9) -> 2029-30 | L4: =INDEX('0_Setup'!$B$48:$B$59,10) | M4: =INDEX('0_Setup'!$B$48:$B$59,11) | N4: =INDEX('0_Setup'!$B$48:$B$59,12)
B5: Type → | C5: =INDEX('0_Setup'!$C$48:$C$59,1) -> Audited | D5: =INDEX('0_Setup'!$C$48:$C$59,2) -> Audited | E5: =INDEX('0_Setup'!$C$48:$C$59,3) -> Estimated | F5: =INDEX('0_Setup'!$C$48:$C$59,4) -> Audited/Provisional | G5: =INDEX('0_Setup'!$C$48:$C$59,5) -> Estimated | H5: =INDEX('0_Setup'!$C$48:$C$59,6) -> Projected | I5: =INDEX('0_Setup'!$C$48:$C$59,7) -> Projected | J5: =INDEX('0_Setup'!$C$48:$C$59,8) -> Projected | K5: =INDEX('0_Setup'!$C$48:$C$59,9) -> Projected | L5: =INDEX('0_Setup'!$C$48:$C$59,10) | M5: =INDEX('0_Setup'!$C$48:$C$59,11) | N5: =INDEX('0_Setup'!$C$48:$C$59,12)
A6: A. SALES
A7: 1 | B7: Domestic Sales
A8: 2 | B8: Export Sales
A9: 3 | B9: Other Operating / Revenue Income
A10: 4 | B10: Total Gross Sales | C10: =C7+C8+C9 -> 0 | D10: =D7+D8+D9 -> 0 | E10: =E7+E8+E9 -> 0 | F10: =F7+F8+F9 -> 0 | G10: =G7+G8+G9 -> 0 | H10: =H7+H8+H9 -> 0 | I10: =I7+I8+I9 -> 0 | J10: =J7+J8+J9 -> 0 | ... N10: =N7+N8+N9 -> 0 | O10: =IFERROR((INDEX(C10:N10,1,LatestAudCol)-INDEX(C10:N10,1,PriorAudCol))/ABS(INDEX(C10:N10,1,PriorAudCol)),"")
A11: 5 | B11: Deduct: Excise Duty / Service Tax
A12: 6 | B12: Deduct: Other Items
A13: 7 | B13: Net Sales | C13: =C10-C11-C12 -> 0 | D13: =D10-D11-D12 -> 0 | E13: =E10-E11-E12 -> 0 | F13: =F10-F11-F12 -> 0 | G13: =G10-G11-G12 -> 0 | H13: =H10-H11-H12 -> 0 | I13: =I10-I11-I12 -> 0 | J13: =J10-J11-J12 -> 0 | ... N13: =N10-N11-N12 -> 0 | O13: =IFERROR((INDEX(C13:N13,1,LatestAudCol)-INDEX(C13:N13,1,PriorAudCol))/ABS(INDEX(C13:N13,1,PriorAudCol)),"")
A14: B. COST OF SALES
A15: 8 | B15: Raw Material - Imported
A16: 9 | B16: Raw Material - Indigenous
A17: 10 | B17: Total Raw Material | C17: =C15+C16 -> 0 | D17: =D15+D16 -> 0 | E17: =E15+E16 -> 0 | F17: =F15+F16 -> 0 | G17: =G15+G16 -> 0 | H17: =H15+H16 -> 0 | I17: =I15+I16 -> 0 | J17: =J15+J16 -> 0 | ... N17: =N15+N16 -> 0
A18: 11 | B18: Spares - Imported
A19: 12 | B19: Spares - Indigenous
A20: 13 | B20: Total Spares | C20: =C18+C19 -> 0 | D20: =D18+D19 -> 0 | E20: =E18+E19 -> 0 | F20: =F18+F19 -> 0 | G20: =G18+G19 -> 0 | H20: =H18+H19 -> 0 | I20: =I18+I19 -> 0 | J20: =J18+J19 -> 0 | ... N20: =N18+N19 -> 0
A21: 14 | B21: Power & Fuel
A22: 15 | B22: Direct Labour
A23: 16 | B23: Other Manufacturing / Direct Costs
A24: 17 | B24: Depreciation & Amortisation
A25: 18 | B25: Add: Opening Stock-in-Process
A26: 19 | B26: Less: Closing Stock-in-Process
A27: 20 | B27: Cost of Production | C27: =C17+C20+C21+C22+C23+C24+C25-C26 -> 0 | D27: =D17+D20+D21+D22+D23+D24+D25-D26 -> 0 | E27: =E17+E20+E21+E22+E23+E24+E25-E26 -> 0 | F27: =F17+F20+F21+F22+F23+F24+F25-F26 -> 0 | G27: =G17+G20+G21+G22+G23+G24+G25-G26 -> 0 | H27: =H17+H20+H21+H22+H23+H24+H25-H26 -> 0 | I27: =I17+I20+I21+I22+I23+I24+I25-I26 -> 0 | J27: =J17+J20+J21+J22+J23+J24+J25-J26 -> 0 | ... N27: =N17+N20+N21+N22+N23+N24+N25-N26 -> 0
A28: 21 | B28: Add: Opening Stock of FG
A29: 22 | B29: Less: Closing Stock of FG
A30: 23 | B30: Cost of Sales | C30: =C27+C28-C29 -> 0 | D30: =D27+D28-D29 -> 0 | E30: =E27+E28-E29 -> 0 | F30: =F27+F28-F29 -> 0 | G30: =G27+G28-G29 -> 0 | H30: =H27+H28-H29 -> 0 | I30: =I27+I28-I29 -> 0 | J30: =J27+J28-J29 -> 0 | ... N30: =N27+N28-N29 -> 0
A31: C. OPERATING PROFIT
A32: 24 | B32: Selling & General Admin Expenses
A33: 25 | B33: Operating Profit Before Interest (OPBI) | C33: =C13-C30-C32 -> 0 | D33: =D13-D30-D32 -> 0 | E33: =E13-E30-E32 -> 0 | F33: =F13-F30-F32 -> 0 | G33: =G13-G30-G32 -> 0 | H33: =H13-H30-H32 -> 0 | I33: =I13-I30-I32 -> 0 | J33: =J13-J30-J32 -> 0 | ... N33: =N13-N30-N32 -> 0 | O33: =IFERROR((INDEX(C33:N33,1,LatestAudCol)-INDEX(C33:N33,1,PriorAudCol))/ABS(INDEX(C33:N33,1,PriorAudCol)),"")
A34: 26 | B34: Interest on Working Capital
A35: 27 | B35: Interest on Term Loans
A36: 28 | B36: Other Finance Charges
A37: 29 | B37: Total Interest Outgo | C37: =C34+C35+C36 -> 0 | D37: =D34+D35+D36 -> 0 | E37: =E34+E35+E36 -> 0 | F37: =F34+F35+F36 -> 0 | G37: =G34+G35+G36 -> 0 | H37: =H34+H35+H36 -> 0 | I37: =I34+I35+I36 -> 0 | J37: =J34+J35+J36 -> 0 | ... N37: =N34+N35+N36 -> 0
A38: 30 | B38: Operating Profit After Interest (OPAI) | C38: =C33-C37 -> 0 | D38: =D33-D37 -> 0 | E38: =E33-E37 -> 0 | F38: =F33-F37 -> 0 | G38: =G33-G37 -> 0 | H38: =H33-H37 -> 0 | I38: =I33-I37 -> 0 | J38: =J33-J37 -> 0 | ... N38: =N33-N37 -> 0 | O38: =IFERROR((INDEX(C38:N38,1,LatestAudCol)-INDEX(C38:N38,1,PriorAudCol))/ABS(INDEX(C38:N38,1,PriorAudCol)),"")
A39: D. OTHER NON-OPERATING
A40: 31 | B40: Interest on Unsecured / Related-party Loans
...

Sheet 3_Balance_Sheet
A1: =CONCATENATE("BALANCE SHEET | ₹ Crores | ", BorrowerName) -> BALANCE SHEET | ₹ Crores |
A2: Liabilities first, then Assets. CHECK row at bottom must = 0.
A3: Sr | B3: Particulars | C3: Yr 1 | D3: Yr 2 | E3: Yr 3 | F3: Yr 4 | G3: Yr 5 | H3: Yr 6 | I3: Yr 7 | J3: Yr 8 | K3: Yr 9 | L3: Yr 10 | M3: Yr 11 | N3: Yr 12 | O3: Δ Latest vs Prior Aud | P3: Auto-Comment
B4: Year → | C4: =INDEX('0_Setup'!$B$48:$B$59,1) -> 2022-23 | D4: =INDEX('0_Setup'!$B$48:$B$59,2) -> 2023-24 | E4: =INDEX('0_Setup'!$B$48:$B$59,3) -> 2024-25 | F4: =INDEX('0_Setup'!$B$48:$B$59,4) -> 2024-25 | G4: =INDEX('0_Setup'!$B$48:$B$59,5) -> 2025-26 | H4: =INDEX('0_Setup'!$B$48:$B$59,6) -> 2026-27 | I4: =INDEX('0_Setup'!$B$48:$B$59,7) -> 2027-28 | J4: =INDEX('0_Setup'!$B$48:$B$59,8) -> 2028-29 | K4: =INDEX('0_Setup'!$B$48:$B$59,9) -> 2029-30 | L4: =INDEX('0_Setup'!$B$48:$B$59,10) | M4: =INDEX('0_Setup'!$B$48:$B$59,11) | N4: =INDEX('0_Setup'!$B$48:$B$59,12)
B5: Type → | C5: =INDEX('0_Setup'!$C$48:$C$59,1) -> Audited | D5: =INDEX('0_Setup'!$C$48:$C$59,2) -> Audited | E5: =INDEX('0_Setup'!$C$48:$C$59,3) -> Estimated | F5: =INDEX('0_Setup'!$C$48:$C$59,4) -> Audited/Provisional | G5: =INDEX('0_Setup'!$C$48:$C$59,5) -> Estimated | H5: =INDEX('0_Setup'!$C$48:$C$59,6) -> Projected | I5: =INDEX('0_Setup'!$C$48:$C$59,7) -> Projected | J5: =INDEX('0_Setup'!$C$48:$C$59,8) -> Projected | K5: =INDEX('0_Setup'!$C$48:$C$59,9) -> Projected | L5: =INDEX('0_Setup'!$C$48:$C$59,10) | M5: =INDEX('0_Setup'!$C$48:$C$59,11) | N5: =INDEX('0_Setup'!$C$48:$C$59,12)
A6: CURRENT LIABILITIES — Short Term Borrowings from Banks
A7: 1 | B7: From Applicant Bank
A8: 2 | B8: From Other Banks
A9: 3 | B9: Under Buyers Credit
A10: 4 | B10: (of which Bills Purchased & Discounted)
A11: 5 | B11: Total Short Term Borrowings from Banks | C11: =C7+C8+C9 -> 0 | D11: =D7+D8+D9 -> 0 | E11: =E7+E8+E9 -> 0 | F11: =F7+F8+F9 -> 0 | G11: =G7+G8+G9 -> 0 | H11: =H7+H8+H9 -> 0 | I11: =I7+I8+I9 -> 0 | J11: =J7+J8+J9 -> 0 | ... N11: =N7+N8+N9 -> 0
A12: CURRENT LIABILITIES — Others
A13: 6 | B13: Short Term Borrowings from Others
A14: 7 | B14: Sundry Creditors (Trade — Without LC)
A15: 8 | B15: Sundry Creditors (Trade — Under LC)
A16: 9 | B16: Advance from Customers & Dealer Deposits
A17: 10 | B17: Provision for Taxation
A18: 11 | B18: Dividend Payable (incl. Tax)
A19: 12 | B19: Other Statutory Liab. (within 1 yr)
A20: 13 | B20: TL Instalments (within 1 yr)
A21: 14 | B21: Other CL & Provisions (within 1 yr)
A22: 15 | B22: Provision for Expenditure
A23: 16 | B23: Sundry Creditors for Capital Goods
A24: 17 | B24: Sundry Creditors for Expenses
A25: 18 | B25: Others (Current Liab.)
A26: 19 | B26: Total Other Current Liabilities | C26: =SUM(C13:C25) -> 0 | D26: =SUM(D13:D25) -> 0 | E26: =SUM(E13:E25) -> 0 | F26: =SUM(F13:F25) -> 0 | G26: =SUM(G13:G25) -> 0 | H26: =SUM(H13:H25) -> 0 | I26: =SUM(I13:I25) -> 0 | J26: =SUM(J13:J25) -> 0 | ... N26: =SUM(N13:N25) -> 0
A27: 20 | B27: Total Current Liabilities (TCL) | C27: =C11+C26 -> 0 | D27: =D11+D26 -> 0 | E27: =E11+E26 -> 0 | F27: =F11+F26 -> 0 | G27: =G11+G26 -> 0 | H27: =H11+H26 -> 0 | I27: =I11+I26 -> 0 | J27: =J11+J26 -> 0 | ... N27: =N11+N26 -> 0 | O27: =IFERROR((INDEX(C27:N27,1,LatestAudCol)-INDEX(C27:N27,1,PriorAudCol))/ABS(INDEX(C27:N27,1,PriorAudCol)),"")
A28: TERM LIABILITIES
A29: 21 | B29: Debentures (>1 yr)
A30: 22 | B30: Preference Shares (1-12 yrs)
A31: 23 | B31: Secured Term Loans (excl. <1yr instalments)
A32: 24 | B32: Deferred Payment Credits (excl. <1yr instalments)
A33: 25 | B33: Term/Public Deposits (>1 yr)
A34: 26 | B34: Unsecured Loans from Promoters / Group Cos
A35: 27 | B35: Unsecured Loans — Others
A36: 28 | B36: Capex Creditors (>1 yr)
A37: 29 | B37: Non-Current Provisions
A38: 30 | B38: Deferred Tax Liabilities
A39: 31 | B39: Total Term Liabilities (TTL) | C39: =SUM(C29:C38) -> 0 | D39: =SUM(D29:D38) -> 0 | E39: =SUM(E29:E38) -> 0 | F39: =SUM(F29:F38) -> 0 | G39: =SUM(G29:G38) -> 0 | H39: =SUM(H29:H38) -> 0 | I39: =SUM(I29:I38) -> 0 | J39: =SUM(J29:J38) -> 0 | ... N39: =SUM(N29:N38) -> 0 | O39: =IFERROR((INDEX(C39:N39,1,LatestAudCol)-INDEX(C39:N39,1,PriorAudCol))/ABS(INDEX(C39:N39,1,PriorAudCol)),"")
A40: 32 | B40: Total Outside Liabilities (TOL) | C40: =C27+C39 -> 0 | D40: =D27+D39 -> 0 | E40: =E27+E39 -> 0 | F40: =F27+F39 -> 0 | G40: =G27+G39 -> 0 | H40: =H27+H39 -> 0 | I40: =I27+I39 -> 0 | J40: =J27+J39 -> 0 | ... N40: =N27+N39 -> 0 | O40: =IFERROR((INDEX(C40:N40,1,LatestAudCol)-INDEX(C40:N40,1,PriorAudCol))/ABS(INDEX(C40:N40,1,PriorAudCol)),"")
...

Sheet 4_DSCR
A1: =CONCATENATE("DSCR CALCULATION | ₹ Crores | ", BorrowerName) -> DSCR CALCULATION | ₹ Crores |
A2: Cash Accruals + Interest pulled from Operating Statement automatically.
A3: Sr | B3: Particulars | C3: Yr 1 | D3: Yr 2 | E3: Yr 3 | F3: Yr 4 | G3: Yr 5 | H3: Yr 6 | I3: Yr 7 | J3: Yr 8 | K3: Yr 9 | L3: Yr 10 | M3: Yr 11 | N3: Yr 12 | O3: Δ Latest vs Prior Aud | P3: Auto-Comment
B4: Year → | C4: =INDEX('0_Setup'!$B$48:$B$59,1) -> 2022-23 | D4: =INDEX('0_Setup'!$B$48:$B$59,2) -> 2023-24 | E4: =INDEX('0_Setup'!$B$48:$B$59,3) -> 2024-25 | F4: =INDEX('0_Setup'!$B$48:$B$59,4) -> 2024-25 | G4: =INDEX('0_Setup'!$B$48:$B$59,5) -> 2025-26 | H4: =INDEX('0_Setup'!$B$48:$B$59,6) -> 2026-27 | I4: =INDEX('0_Setup'!$B$48:$B$59,7) -> 2027-28 | J4: =INDEX('0_Setup'!$B$48:$B$59,8) -> 2028-29 | K4: =INDEX('0_Setup'!$B$48:$B$59,9) -> 2029-30 | L4: =INDEX('0_Setup'!$B$48:$B$59,10) | M4: =INDEX('0_Setup'!$B$48:$B$59,11) | N4: =INDEX('0_Setup'!$B$48:$B$59,12)
B5: Type → | C5: =INDEX('0_Setup'!$C$48:$C$59,1) -> Audited | D5: =INDEX('0_Setup'!$C$48:$C$59,2) -> Audited | E5: =INDEX('0_Setup'!$C$48:$C$59,3) -> Estimated | F5: =INDEX('0_Setup'!$C$48:$C$59,4) -> Audited/Provisional | G5: =INDEX('0_Setup'!$C$48:$C$59,5) -> Estimated | H5: =INDEX('0_Setup'!$C$48:$C$59,6) -> Projected | I5: =INDEX('0_Setup'!$C$48:$C$59,7) -> Projected | J5: =INDEX('0_Setup'!$C$48:$C$59,8) -> Projected | K5: =INDEX('0_Setup'!$C$48:$C$59,9) -> Projected | L5: =INDEX('0_Setup'!$C$48:$C$59,10) | M5: =INDEX('0_Setup'!$C$48:$C$59,11) | N5: =INDEX('0_Setup'!$C$48:$C$59,12)
A6: A. CASH ACCRUALS
A7: 1 | B7: PAT + Depreciation (Cash Accruals) | C7: ='2_Operating_Statement'!C58+'2_Operating_Statement'!C24 -> 0 | D7: ='2_Operating_Statement'!D58+'2_Operating_Statement'!D24 -> 0 | E7: ='2_Operating_Statement'!E58+'2_Operating_Statement'!E24 -> 0 | F7: ='2_Operating_Statement'!F58+'2_Operating_Statement'!F24 -> 0 | G7: ='2_Operating_Statement'!G58+'2_Operating_Statement'!G24 -> 0 | H7: ='2_Operating_Statement'!H58+'2_Operating_Statement'!H24 -> 0 | I7: ='2_Operating_Statement'!I58+'2_Operating_Statement'!I24 -> 0 | J7: ='2_Operating_Statement'!J58+'2_Operating_Statement'!J24 -> 0 | ... N7: ='2_Operating_Statement'!N58+'2_Operating_Statement'!N24 -> 0
A8: 2 | B8: Less: Cash Accruals utilised in projects by Borrower
A9: 3 | B9: Net Cash Accruals available for Debt Service | C9: =C7-C8 -> 0 | D9: =D7-D8 -> 0 | E9: =E7-E8 -> 0 | F9: =F7-F8 -> 0 | G9: =G7-G8 -> 0 | H9: =H7-H8 -> 0 | I9: =I7-I8 -> 0 | J9: =J7-J8 -> 0 | ... N9: =N7-N8 -> 0
A10: B. DEBT SERVICE OBLIGATIONS
A11: 4 | B11: TL Instalments — Applicant Bank
A12: 5 | B12: TL Instalments — Other Banks
A13: 6 | B13: Total TL Instalments (All Banks) | C13: =C11+C12 -> 0 | D13: =D11+D12 -> 0 | E13: =E11+E12 -> 0 | F13: =F11+F12 -> 0 | G13: =G11+G12 -> 0 | H13: =H11+H12 -> 0 | I13: =I11+I12 -> 0 | J13: =J11+J12 -> 0 | ... N13: =N11+N12 -> 0
A14: 7 | B14: Interest on Term Loans (from Op Stmt) | C14: ='2_Operating_Statement'!C35 -> 0 | D14: ='2_Operating_Statement'!D35 -> 0 | E14: ='2_Operating_Statement'!E35 -> 0 | F14: ='2_Operating_Statement'!F35 -> 0 | G14: ='2_Operating_Statement'!G35 -> 0 | H14: ='2_Operating_Statement'!H35 -> 0 | I14: ='2_Operating_Statement'!I35 -> 0 | J14: ='2_Operating_Statement'!J35 -> 0 | ... N14: ='2_Operating_Statement'!N35 -> 0
A15: 8 | B15: Total Debt Service | C15: =C13+C14 -> 0 | D15: =D13+D14 -> 0 | E15: =E13+E14 -> 0 | F15: =F13+F14 -> 0 | G15: =G13+G14 -> 0 | H15: =H13+H14 -> 0 | I15: =I13+I14 -> 0 | J15: =J13+J14 -> 0 | ... N15: =N13+N14 -> 0
A16: C. DSCR RATIOS
A17: 9 | B17: Gross DSCR = (NCA + Int TL) / (Inst + Int TL) | C17: =IFERROR((C9+C14)/(C13+C14),0) -> 0 | D17: =IFERROR((D9+D14)/(D13+D14),0) -> 0 | E17: =IFERROR((E9+E14)/(E13+E14),0) -> 0 | F17: =IFERROR((F9+F14)/(F13+F14),0) -> 0 | G17: =IFERROR((G9+G14)/(G13+G14),0) -> 0 | H17: =IFERROR((H9+H14)/(H13+H14),0) -> 0 | I17: =IFERROR((I9+I14)/(I13+I14),0) -> 0 | J17: =IFERROR((J9+J14)/(J13+J14),0) -> 0 | ... N17: =IFERROR((N9+N14)/(N13+N14),0) -> 0
A18: 10 | B18: Net DSCR = NCA / Instalments | C18: =IFERROR(C9/C13,0) -> 0 | D18: =IFERROR(D9/D13,0) -> 0 | E18: =IFERROR(E9/E13,0) -> 0 | F18: =IFERROR(F9/F13,0) -> 0 | G18: =IFERROR(G9/G13,0) -> 0 | H18: =IFERROR(H9/H13,0) -> 0 | I18: =IFERROR(I9/I13,0) -> 0 | J18: =IFERROR(J9/J13,0) -> 0 | ... N18: =IFERROR(N9/N13,0) -> 0
A19: 11 | B19: Average Gross DSCR (over years with TL instalments) | C19: =IFERROR(AVERAGEIF(C13:N13,">0",C17:N17),0) -> 0 | P19: =IF(C19<MinDSCR_Avg,"⚠ Average DSCR "&TEXT(C19,"0.00x")&" below threshold of "&TEXT(MinDSCR_Avg,"0.00x"),"✓ Average DSCR "&TEXT(C19,"0.00x")&" meets threshold") -> ⚠ Average DSCR 0.00x below threshold of 1.50x
A21: PROJECT FINANCE OVERLAY (DSCR threshold suppression for construction phase)
A22: =IF(ProjectFinance="Yes","⚠ This is a Project Finance facility (Phase: "&ProjectPhase&"). "&IF(ProjectPhase="Under-Construction","DSCR thresholds are SUPPRESSED during construction years. Greenfield projects generate zero cash flows pre-DCCO; apply DSCR covenant only from FY"&IF(DCCO_Year="","[DCCO not set]",DCCO_Year)&" onwards. Validate via Construction Period Interest moratorium and DSRA arrangement per RBI Project Finance Directions 2025.","Project is operational — standard DSCR covenants apply across all years."),"Standard corporate facility — DSCR covenants apply across all projection years per Setup thresholds.") -> Standard corporate facility — DSCR covenants apply across all projection years per Setup thresholds.

Sheet 5_Holding_Levels
A1: =CONCATENATE("HOLDING LEVELS | ", BorrowerName) -> HOLDING LEVELS |
A2: Inventory & receivables/payables in months. Auto-pulled where possible.
A3: Sr | B3: Particulars | C3: Yr 1 | D3: Yr 2 | E3: Yr 3 | F3: Yr 4 | G3: Yr 5 | H3: Yr 6 | I3: Yr 7 | J3: Yr 8 | K3: Yr 9 | L3: Yr 10 | M3: Yr 11 | N3: Yr 12 | O3: Δ Latest vs Prior Aud | P3: Auto-Comment
B4: Year → | C4: =INDEX('0_Setup'!$B$48:$B$59,1) -> 2022-23 | D4: =INDEX('0_Setup'!$B$48:$B$59,2) -> 2023-24 | E4: =INDEX('0_Setup'!$B$48:$B$59,3) -> 2024-25 | F4: =INDEX('0_Setup'!$B$48:$B$59,4) -> 2024-25 | G4: =INDEX('0_Setup'!$B$48:$B$59,5) -> 2025-26 | H4: =INDEX('0_Setup'!$B$48:$B$59,6) -> 2026-27 | I4: =INDEX('0_Setup'!$B$48:$B$59,7) -> 2027-28 | J4: =INDEX('0_Setup'!$B$48:$B$59,8) -> 2028-29 | K4: =INDEX('0_Setup'!$B$48:$B$59,9) -> 2029-30 | L4: =INDEX('0_Setup'!$B$48:$B$59,10) | M4: =INDEX('0_Setup'!$B$48:$B$59,11) | N4: =INDEX('0_Setup'!$B$48:$B$59,12)
B5: Type → | C5: =INDEX('0_Setup'!$C$48:$C$59,1) -> Audited | D5: =INDEX('0_Setup'!$C$48:$C$59,2) -> Audited | E5: =INDEX('0_Setup'!$C$48:$C$59,3) -> Estimated | F5: =INDEX('0_Setup'!$C$48:$C$59,4) -> Audited/Provisional | G5: =INDEX('0_Setup'!$C$48:$C$59,5) -> Estimated | H5: =INDEX('0_Setup'!$C$48:$C$59,6) -> Projected | I5: =INDEX('0_Setup'!$C$48:$C$59,7) -> Projected | J5: =INDEX('0_Setup'!$C$48:$C$59,8) -> Projected | K5: =INDEX('0_Setup'!$C$48:$C$59,9) -> Projected | L5: =INDEX('0_Setup'!$C$48:$C$59,10) | M5: =INDEX('0_Setup'!$C$48:$C$59,11) | N5: =INDEX('0_Setup'!$C$48:$C$59,12)
A6: INVENTORY HOLDING — RAW MATERIAL
A7: 1 | B7: RM Imported (linked from BS) | C7: ='3_Balance_Sheet'!C65 -> 0 | D7: ='3_Balance_Sheet'!D65 -> 0 | E7: ='3_Balance_Sheet'!E65 -> 0 | F7: ='3_Balance_Sheet'!F65 -> 0 | G7: ='3_Balance_Sheet'!G65 -> 0 | H7: ='3_Balance_Sheet'!H65 -> 0 | I7: ='3_Balance_Sheet'!I65 -> 0 | J7: ='3_Balance_Sheet'!J65 -> 0 | ... N7: ='3_Balance_Sheet'!N65 -> 0
A8: 2 | B8: Months' RM Imported consumption | C8: =IFERROR(C7*12/'2_Operating_Statement'!C15,0) -> 0 | D8: =IFERROR(D7*12/'2_Operating_Statement'!D15,0) -> 0 | E8: =IFERROR(E7*12/'2_Operating_Statement'!E15,0) -> 0 | F8: =IFERROR(F7*12/'2_Operating_Statement'!F15,0) -> 0 | G8: =IFERROR(G7*12/'2_Operating_Statement'!G15,0) -> 0 | H8: =IFERROR(H7*12/'2_Operating_Statement'!H15,0) -> 0 | I8: =IFERROR(I7*12/'2_Operating_Statement'!I15,0) -> 0 | J8: =IFERROR(J7*12/'2_Operating_Statement'!J15,0) -> 0 | ... N8: =IFERROR(N7*12/'2_Operating_Statement'!N15,0) -> 0
A9: 3 | B9: RM Indigenous (linked from BS) | C9: ='3_Balance_Sheet'!C66 -> 0 | D9: ='3_Balance_Sheet'!D66 -> 0 | E9: ='3_Balance_Sheet'!E66 -> 0 | F9: ='3_Balance_Sheet'!F66 -> 0 | G9: ='3_Balance_Sheet'!G66 -> 0 | H9: ='3_Balance_Sheet'!H66 -> 0 | I9: ='3_Balance_Sheet'!I66 -> 0 | J9: ='3_Balance_Sheet'!J66 -> 0 | ... N9: ='3_Balance_Sheet'!N66 -> 0
A10: 4 | B10: Months' RM Indigenous consumption | C10: =IFERROR(C9*12/'2_Operating_Statement'!C16,0) -> 0 | D10: =IFERROR(D9*12/'2_Operating_Statement'!D16,0) -> 0 | E10: =IFERROR(E9*12/'2_Operating_Statement'!E16,0) -> 0 | F10: =IFERROR(F9*12/'2_Operating_Statement'!F16,0) -> 0 | G10: =IFERROR(G9*12/'2_Operating_Statement'!G16,0) -> 0 | H10: =IFERROR(H9*12/'2_Operating_Statement'!H16,0) -> 0 | I10: =IFERROR(I9*12/'2_Operating_Statement'!I16,0) -> 0 | J10: =IFERROR(J9*12/'2_Operating_Statement'!J16,0) -> 0 | ... N10: =IFERROR(N9*12/'2_Operating_Statement'!N16,0) -> 0
A11: INVENTORY HOLDING — SPARES
A12: 5 | B12: Spares Imported (override)
A13: 6 | B13: Months' Spares Imported | C13: =IFERROR(C12*12/'2_Operating_Statement'!C18,0) -> 0 | D13: =IFERROR(D12*12/'2_Operating_Statement'!D18,0) -> 0 | E13: =IFERROR(E12*12/'2_Operating_Statement'!E18,0) -> 0 | F13: =IFERROR(F12*12/'2_Operating_Statement'!F18,0) -> 0 | G13: =IFERROR(G12*12/'2_Operating_Statement'!G18,0) -> 0 | H13: =IFERROR(H12*12/'2_Operating_Statement'!H18,0) -> 0 | I13: =IFERROR(I12*12/'2_Operating_Statement'!I18,0) -> 0 | J13: =IFERROR(J12*12/'2_Operating_Statement'!J18,0) -> 0 | ... N13: =IFERROR(N12*12/'2_Operating_Statement'!N18,0) -> 0
A14: 7 | B14: Spares Indigenous (override)
A15: 8 | B15: Months' Spares Indigenous | C15: =IFERROR(C14*12/'2_Operating_Statement'!C19,0) -> 0 | D15: =IFERROR(D14*12/'2_Operating_Statement'!D19,0) -> 0 | E15: =IFERROR(E14*12/'2_Operating_Statement'!E19,0) -> 0 | F15: =IFERROR(F14*12/'2_Operating_Statement'!F19,0) -> 0 | G15: =IFERROR(G14*12/'2_Operating_Statement'!G19,0) -> 0 | H15: =IFERROR(H14*12/'2_Operating_Statement'!H19,0) -> 0 | I15: =IFERROR(I14*12/'2_Operating_Statement'!I19,0) -> 0 | J15: =IFERROR(J14*12/'2_Operating_Statement'!J19,0) -> 0 | ... N15: =IFERROR(N14*12/'2_Operating_Statement'!N19,0) -> 0
A16: INVENTORY HOLDING — WIP & FG
A17: 9 | B17: Stock-in-Process (linked) | C17: ='3_Balance_Sheet'!C68 -> 0 | D17: ='3_Balance_Sheet'!D68 -> 0 | E17: ='3_Balance_Sheet'!E68 -> 0 | F17: ='3_Balance_Sheet'!F68 -> 0 | G17: ='3_Balance_Sheet'!G68 -> 0 | H17: ='3_Balance_Sheet'!H68 -> 0 | I17: ='3_Balance_Sheet'!I68 -> 0 | J17: ='3_Balance_Sheet'!J68 -> 0 | ... N17: ='3_Balance_Sheet'!N68 -> 0
A18: 10 | B18: Months' SIP / Cost of Production | C18: =IFERROR(C17*12/'2_Operating_Statement'!C27,0) -> 0 | D18: =IFERROR(D17*12/'2_Operating_Statement'!D27,0) -> 0 | E18: =IFERROR(E17*12/'2_Operating_Statement'!E27,0) -> 0 | F18: =IFERROR(F17*12/'2_Operating_Statement'!F27,0) -> 0 | G18: =IFERROR(G17*12/'2_Operating_Statement'!G27,0) -> 0 | H18: =IFERROR(H17*12/'2_Operating_Statement'!H27,0) -> 0 | I18: =IFERROR(I17*12/'2_Operating_Statement'!I27,0) -> 0 | J18: =IFERROR(J17*12/'2_Operating_Statement'!J27,0) -> 0 | ... N18: =IFERROR(N17*12/'2_Operating_Statement'!N27,0) -> 0
A19: 11 | B19: Finished Goods (linked) | C19: ='3_Balance_Sheet'!C69 -> 0 | D19: ='3_Balance_Sheet'!D69 -> 0 | E19: ='3_Balance_Sheet'!E69 -> 0 | F19: ='3_Balance_Sheet'!F69 -> 0 | G19: ='3_Balance_Sheet'!G69 -> 0 | H19: ='3_Balance_Sheet'!H69 -> 0 | I19: ='3_Balance_Sheet'!I69 -> 0 | J19: ='3_Balance_Sheet'!J69 -> 0 | ... N19: ='3_Balance_Sheet'!N69 -> 0
A20: 12 | B20: Months' FG / Cost of Sales | C20: =IFERROR(C19*12/'2_Operating_Statement'!C30,0) -> 0 | D20: =IFERROR(D19*12/'2_Operating_Statement'!D30,0) -> 0 | E20: =IFERROR(E19*12/'2_Operating_Statement'!E30,0) -> 0 | F20: =IFERROR(F19*12/'2_Operating_Statement'!F30,0) -> 0 | G20: =IFERROR(G19*12/'2_Operating_Statement'!G30,0) -> 0 | H20: =IFERROR(H19*12/'2_Operating_Statement'!H30,0) -> 0 | I20: =IFERROR(I19*12/'2_Operating_Statement'!I30,0) -> 0 | J20: =IFERROR(J19*12/'2_Operating_Statement'!J30,0) -> 0 | ... N20: =IFERROR(N19*12/'2_Operating_Statement'!N30,0) -> 0
A21: RECEIVABLES
A22: 13 | B22: Domestic Receivables (linked) | C22: ='3_Balance_Sheet'!C59 -> 0 | D22: ='3_Balance_Sheet'!D59 -> 0 | E22: ='3_Balance_Sheet'!E59 -> 0 | F22: ='3_Balance_Sheet'!F59 -> 0 | G22: ='3_Balance_Sheet'!G59 -> 0 | H22: ='3_Balance_Sheet'!H59 -> 0 | I22: ='3_Balance_Sheet'!I59 -> 0 | J22: ='3_Balance_Sheet'!J59 -> 0 | ... N22: ='3_Balance_Sheet'!N59 -> 0
A23: 14 | B23: Months' Domestic Sales (excl. exports) | C23: =IFERROR(C22*12/'2_Operating_Statement'!C7,0) -> 0 | D23: =IFERROR(D22*12/'2_Operating_Statement'!D7,0) -> 0 | E23: =IFERROR(E22*12/'2_Operating_Statement'!E7,0) -> 0 | F23: =IFERROR(F22*12/'2_Operating_Statement'!F7,0) -> 0 | G23: =IFERROR(G22*12/'2_Operating_Statement'!G7,0) -> 0 | H23: =IFERROR(H22*12/'2_Operating_Statement'!H7,0) -> 0 | I23: =IFERROR(I22*12/'2_Operating_Statement'!I7,0) -> 0 | J23: =IFERROR(J22*12/'2_Operating_Statement'!J7,0) -> 0 | ... N23: =IFERROR(N22*12/'2_Operating_Statement'!N7,0) -> 0
A24: 15 | B24: Export Receivables (linked) | C24: ='3_Balance_Sheet'!C60 -> 0 | D24: ='3_Balance_Sheet'!D60 -> 0 | E24: ='3_Balance_Sheet'!E60 -> 0 | F24: ='3_Balance_Sheet'!F60 -> 0 | G24: ='3_Balance_Sheet'!G60 -> 0 | H24: ='3_Balance_Sheet'!H60 -> 0 | I24: ='3_Balance_Sheet'!I60 -> 0 | J24: ='3_Balance_Sheet'!J60 -> 0 | ... N24: ='3_Balance_Sheet'!N60 -> 0
A25: 16 | B25: Months' Export Sales | C25: =IFERROR(C24*12/'2_Operating_Statement'!C8,0) -> 0 | D25: =IFERROR(D24*12/'2_Operating_Statement'!D8,0) -> 0 | E25: =IFERROR(E24*12/'2_Operating_Statement'!E8,0) -> 0 | F25: =IFERROR(F24*12/'2_Operating_Statement'!F8,0) -> 0 | G25: =IFERROR(G24*12/'2_Operating_Statement'!G8,0) -> 0 | H25: =IFERROR(H24*12/'2_Operating_Statement'!H8,0) -> 0 | I25: =IFERROR(I24*12/'2_Operating_Statement'!I8,0) -> 0 | J25: =IFERROR(J24*12/'2_Operating_Statement'!J8,0) -> 0 | ... N25: =IFERROR(N24*12/'2_Operating_Statement'!N8,0) -> 0
A26: OTHER CURRENT ASSETS
A27: 17 | B27: Cash & Bank Balances | C27: ='3_Balance_Sheet'!C55 -> 0 | D27: ='3_Balance_Sheet'!D55 -> 0 | E27: ='3_Balance_Sheet'!E55 -> 0 | F27: ='3_Balance_Sheet'!F55 -> 0 | G27: ='3_Balance_Sheet'!G55 -> 0 | H27: ='3_Balance_Sheet'!H55 -> 0 | I27: ='3_Balance_Sheet'!I55 -> 0 | J27: ='3_Balance_Sheet'!J55 -> 0 | ... N27: ='3_Balance_Sheet'!N55 -> 0
A28: 18 | B28: Govt & Other Trustee Securities | C28: ='3_Balance_Sheet'!C56 -> 0 | D28: ='3_Balance_Sheet'!D56 -> 0 | E28: ='3_Balance_Sheet'!E56 -> 0 | F28: ='3_Balance_Sheet'!F56 -> 0 | G28: ='3_Balance_Sheet'!G56 -> 0 | H28: ='3_Balance_Sheet'!H56 -> 0 | I28: ='3_Balance_Sheet'!I56 -> 0 | J28: ='3_Balance_Sheet'!J56 -> 0 | ... N28: ='3_Balance_Sheet'!N56 -> 0
A29: 19 | B29: Fixed Deposits with Banks | C29: ='3_Balance_Sheet'!C57 -> 0 | D29: ='3_Balance_Sheet'!D57 -> 0 | E29: ='3_Balance_Sheet'!E57 -> 0 | F29: ='3_Balance_Sheet'!F57 -> 0 | G29: ='3_Balance_Sheet'!G57 -> 0 | H29: ='3_Balance_Sheet'!H57 -> 0 | I29: ='3_Balance_Sheet'!I57 -> 0 | J29: ='3_Balance_Sheet'!J57 -> 0 | ... N29: ='3_Balance_Sheet'!N57 -> 0
A30: 20 | B30: Total Current Assets (linked from BS) | C30: ='3_Balance_Sheet'!C82 -> 0 | D30: ='3_Balance_Sheet'!D82 -> 0 | E30: ='3_Balance_Sheet'!E82 -> 0 | F30: ='3_Balance_Sheet'!F82 -> 0 | G30: ='3_Balance_Sheet'!G82 -> 0 | H30: ='3_Balance_Sheet'!H82 -> 0 | I30: ='3_Balance_Sheet'!I82 -> 0 | J30: ='3_Balance_Sheet'!J82 -> 0 | ... N30: ='3_Balance_Sheet'!N82 -> 0
A31: CURRENT LIABILITIES
A32: 21 | B32: Sundry Creditors (Trade — linked) | C32: ='3_Balance_Sheet'!C14+'3_Balance_Sheet'!C15 -> 0 | D32: ='3_Balance_Sheet'!D14+'3_Balance_Sheet'!D15 -> 0 | E32: ='3_Balance_Sheet'!E14+'3_Balance_Sheet'!E15 -> 0 | F32: ='3_Balance_Sheet'!F14+'3_Balance_Sheet'!F15 -> 0 | G32: ='3_Balance_Sheet'!G14+'3_Balance_Sheet'!G15 -> 0 | H32: ='3_Balance_Sheet'!H14+'3_Balance_Sheet'!H15 -> 0 | I32: ='3_Balance_Sheet'!I14+'3_Balance_Sheet'!I15 -> 0 | J32: ='3_Balance_Sheet'!J14+'3_Balance_Sheet'!J15 -> 0 | ... N32: ='3_Balance_Sheet'!N14+'3_Balance_Sheet'!N15 -> 0
A33: 22 | B33: Months' Purchases (Sundry Creditors) | C33: =IFERROR(C32*12/('2_Operating_Statement'!C17+'2_Operating_Statement'!C20),0) -> 0 | D33: =IFERROR(D32*12/('2_Operating_Statement'!D17+'2_Operating_Statement'!D20),0) -> 0 | E33: =IFERROR(E32*12/('2_Operating_Statement'!E17+'2_Operating_Statement'!E20),0) -> 0 | F33: =IFERROR(F32*12/('2_Operating_Statement'!F17+'2_Operating_Statement'!F20),0) -> 0 | G33: =IFERROR(G32*12/('2_Operating_Statement'!G17+'2_Operating_Statement'!G20),0) -> 0 | H33: =IFERROR(H32*12/('2_Operating_Statement'!H17+'2_Operating_Statement'!H20),0) -> 0 | I33: =IFERROR(I32*12/('2_Operating_Statement'!I17+'2_Operating_Statement'!I20),0) -> 0 | J33: =IFERROR(J32*12/('2_Operating_Statement'!J17+'2_Operating_Statement'!J20),0) -> 0 | ... N33: =IFERROR(N32*12/('2_Operating_Statement'!N17+'2_Operating_Statement'!N20),0) -> 0
A34: 23 | B34: TL Instalments (within 1 yr — linked) | C34: ='3_Balance_Sheet'!C20 -> 0 | D34: ='3_Balance_Sheet'!D20 -> 0 | E34: ='3_Balance_Sheet'!E20 -> 0 | F34: ='3_Balance_Sheet'!F20 -> 0 | G34: ='3_Balance_Sheet'!G20 -> 0 | H34: ='3_Balance_Sheet'!H20 -> 0 | I34: ='3_Balance_Sheet'!I20 -> 0 | J34: ='3_Balance_Sheet'!J20 -> 0 | ... N34: ='3_Balance_Sheet'!N20 -> 0

Sheet 6_Working_Capital
